Workbook

Sheet Sheet1
A1: Job Type
A2: Name
A3: Date
A4: District
A5: Township
A6: Payment Method
A7: Road Name
A8: Road Limits
A9: Comments
A10: Length (feet)
A11: Width (feet)
A12: Depth (inches)
... A24: Notes

Sheet Limestone
B1: GENESEE COUNTY ROAD COMMISSION | H1: GENESEE COUNTY ROAD COMMISSION
B2: MAINTENANCE DEPARTMENT | H2: MAINTENANCE DEPARTMENT
B3: ="COST FOR "& UPPER(Sheet1!B1) -> COST FOR | H3: 211 West Oakley Street Flint, Michigan 48503-3995
B4: TOWNSHIP OF | C4: =LEFT(Sheet1!B5, LEN(Sheet1!B5)-9) -> #VALUE! | G4: ="COST FOR "& UPPER(Sheet1!B1) -> COST FOR
B5: ROAD NAME: | C5: =Sheet1!B7 -> 0
B6: LENGTH: | C6: =Sheet1!B10&"' X "&Sheet1!B11&"' X "&Sheet1!B12&"""" -> ' X ' X " | G6: DATE | H6: =Sheet1!B3 -> 0 | J6: TOWNSHIP OF | M6: =C4 -> #VALUE!
B7: TYPE OF WORK: | C7: =Sheet1!B1 -> 0
B8: COMMENTS | C8: =Sheet1!B9 -> 0 | G8: ROAD NAME: | H8: =C5 -> 0
A9: I. Labor | G9: LENGTH: | H9: =C6 -> ' X ' X " | M9: Miles: | N9: =Sheet1!B10/5280 -> 0
A10: LABOR - Regular | C10: QTY | D10: UNIT | E10: UNIT COST | F10: TOTAL | G10: TYPE OF WORK: | H10: =C7 -> 0
A11: =Sheet1!B14 -> 0 | B11: Equipment Operator | C11: =Sheet1!B16 -> 0 | D11: Hr | E11: 32.47 | F11: =A11*C11*E11 -> 0 | G11: ADDITIONAL COMMENTS | H11: *Prices good for the 2025/2026 FY* | K11: Final accounting will be based on actual cost
A12: =Sheet1!B15 -> 0 | B12: Foreman | C12: =Sheet1!B17 -> 0 | D12: Hr | E12: 41.31 | F12: =A12*C12*E12 -> 0 | H12: =C8 -> 0
A13: LABOR - OT | C13: QTY | D13: UNIT | E13: UNIT COST | F13: TOTAL
A14: =Sheet1!B18 -> 0 | B14: Equipment Operator | C14: =Sheet1!B20 -> 0 | D14: Hr | E14: 48.71 | F14: =A14*C14*E14 -> 0 | I14: SUMMARY OF ESTIMATED COST
A15: =Sheet1!B19 -> 0 | B15: Foreman | C15: =Sheet1!B21 -> 0 | D15: Hr | E15: 61.97 | F15: =A15*C15*E15 -> 0 | I15: Estimated Time Needed to Complete Work
C16: Subtotal Days | E16: =Sheet1!B13 -> 0 | F16: =SUM(F11:F15)*K16 -> 0 | J16: Day/Days | K16: =Sheet1!B13 -> 0
A17: Sub Total Man Hours | C17: =(SUM(A11*C11)+(A12*C12)+(A14*C14)+(A15*C15))*K16 -> 0 | D17: Fringe | E17: 1.043569 | F17: =F16*E17 -> 0
A18: Total Labor & Fringe | C18: . | F18: =F16+F17 -> 0 | J18: GRAND TOTAL | K18: =F47 -> 0
A19: II. Equipment
A20: Equipment Description | C20: QTY | D20: UNIT | E20: UNIT COST | F20: TOTAL | I20: Township Participation | K20: =K18*(Sheet1!#REF!/100) -> #REF!
A21: =Sheet1!C26 -> 0 | B21: =Sheet1!B26&" - #"&Sheet1!E26 -> - # | C21: =Sheet1!D26 -> 0 | D21: Hr | E21: =LOOKUP(Sheet1!E26,Table336789101112131415[Equip Number], Table336789101112131415[Sched C/ County/ State]) -> #N/A | F21: =E21*A21*C21 -> #N/A
A22: =Sheet1!C27 -> 0 | B22: =Sheet1!B27&" - #"&Sheet1!E27 -> - # | C22: =Sheet1!D27 -> 0 | D22: Hr | E22: =LOOKUP(Sheet1!E27,Table336789101112131415[Equip Number], Table336789101112131415[Sched C/ County/ State]) -> #N/A | F22: =E22*A22*C22 -> #N/A | I22: GCRC Allocation Funds | K22: =K18*(Sheet1!#REF!/100) -> #REF!
A23: =Sheet1!C28 -> 0 | B23: =Sheet1!B28&" - #"&Sheet1!E28 -> - # | C23: =Sheet1!D28 -> 0 | D23: Hr | E23: =LOOKUP(Sheet1!E28,Table336789101112131415[Equip Number], Table336789101112131415[Sched C/ County/ State]) -> #N/A | F23: =E23*A23*C23 -> #N/A
A24: =Sheet1!C29 -> 0 | B24: =Sheet1!B29&" - #"&Sheet1!E29 -> - # | C24: =Sheet1!D29 -> 0 | D24: Hr | E24: =LOOKUP(Sheet1!E29,Table336789101112131415[Equip Number], Table336789101112131415[Sched C/ County/ State]) -> #N/A | F24: =E24*A24*C24 -> #N/A | I24: Participation by Others | M24: Source: ___________________
A25: =Sheet1!C30 -> 0 | B25: =Sheet1!B30&" - #"&Sheet1!E30 -> - # | C25: =Sheet1!D30 -> 0 | D25: Hr | E25: =LOOKUP(Sheet1!E30,Table336789101112131415[Equip Number], Table336789101112131415[Sched C/ County/ State]) -> #N/A | F25: =E25*A25*C25 -> #N/A
A26: =Sheet1!C31 -> 0 | B26: =Sheet1!B31&" - #"&Sheet1!E31 -> - # | C26: =Sheet1!D31 -> 0 | D26: Hr | E26: =LOOKUP(Sheet1!E31,Table336789101112131415[Equip Number], Table336789101112131415[Sched C/ County/ State]) -> #N/A | F26: =E26*A26*C26 -> #N/A | H26: Community Development Block Grant (CDBG) | K26: Yes | M26: No
A27: =Sheet1!C32 -> 0 | B27: =Sheet1!B32&" - #"&Sheet1!E32 -> - # | C27: =Sheet1!D32 -> 0 | D27: Hr | E27: =LOOKUP(Sheet1!E32,Table336789101112131415[Equip Number], Table336789101112131415[Sched C/ County/ State]) -> #N/A | F27: =E27*A27*C27 -> #N/A
A28: =Sheet1!C33 -> 0 | B28: =Sheet1!B33&" - #"&Sheet1!E33 -> - # | C28: =Sheet1!D33 -> 0 | D28: Hr | E28: =LOOKUP(Sheet1!E33,Table336789101112131415[Equip Number], Table336789101112131415[Sched C/ County/ State]) -> #N/A | F28: =E28*A28*C28 -> #N/A | G28: Please sign below and return to the Maintenance Department, if your Township would like the Genesee County Road
A29: =Sheet1!C34 -> 0 | B29: =Sheet1!B34&" - #"&Sheet1!E34 -> - # | C29: =Sheet1!D34 -> 0 | D29: Hr | E29: =LOOKUP(Sheet1!E34,Table336789101112131415[Equip Number], Table336789101112131415[Sched C/ County/ State]) -> #N/A | F29: =E29*A29*C29 -> #N/A | G29: Commission to proceed with this work. It is agreed that in the event the cost exceeds more than 10% of above
A30: =Sheet1!C35 -> 0 | B30: =Sheet1!B35&" - #"&Sheet1!E35 -> - # | C30: =Sheet1!D35 -> 0 | D30: Hr | E30: =LOOKUP(Sheet1!E35,Table336789101112131415[Equip Number], Table336789101112131415[Sched C/ County/ State]) -> #N/A | F30: =E30*A30*C30 -> #N/A | G30: estimate, the Road Commission will consult with the Township prior to final billing.
A31: =Sheet1!C36 -> 0 | B31: =Sheet1!B36&" - #"&Sheet1!E36 -> - # | C31: =Sheet1!D36 -> 0 | D31: Hr | E31: =LOOKUP(Sheet1!E36,Table336789101112131415[Equip Number], Table336789101112131415[Sched C/ County/ State]) -> #N/A | F31: =E31*A31*C31 -> #N/A
A32: =Sheet1!C37 -> 0 | B32: =Sheet1!B37&" - #"&Sheet1!E37 -> - # | C32: =Sheet1!D37 -> 0 | D32: Hr | E32: =LOOKUP(Sheet1!E37,Table336789101112131415[Equip Number], Table336789101112131415[Sched C/ County/ State]) -> #N/A | F32: =E32*A32*C32 -> #N/A | H32: Township's Board Approval
A33: =Sheet1!C38 -> 0 | B33: =Sheet1!B38&" - #"&Sheet1!E38 -> - # | C33: =Sheet1!D38 -> 0 | D33: Hr | E33: =LOOKUP(Sheet1!E38,Table336789101112131415[Equip Number], Table336789101112131415[Sched C/ County/ State]) -> #N/A | F33: =E33*A33*C33 -> #N/A | J33: Supervisor | N33: Date
A34: =Sheet1!C39 -> 0 | B34: =Sheet1!B39&" - #"&Sheet1!E39 -> - # | C34: =Sheet1!D39 -> 0 | D34: Hr | E34: =LOOKUP(Sheet1!E39,Table336789101112131415[Equip Number], Table336789101112131415[Sched C/ County/ State]) -> #N/A | F34: =E34*A34*C34 -> #N/A | H34: Road Commission's Board Approval
A35: =Sheet1!C40 -> 0 | B35: =Sheet1!B40&" - #"&Sheet1!E40 -> - # | C35: =Sheet1!D40 -> 0 | D35: Hr | E35: =LOOKUP(Sheet1!E40,Table336789101112131415[Equip Number], Table336789101112131415[Sched C/ County/ State]) -> #N/A | F35: =E35*A35*C35 -> #N/A | J35: Chairperson | N35: Date
A36: =Sheet1!C41 -> 0 | B36: =Sheet1!B41&" - #"&Sheet1!E41 -> - # | C36: =Sheet1!D41 -> 0 | D36: Hr | E36: =LOOKUP(Sheet1!E41,Table336789101112131415[Equip Number], Table336789101112131415[Sched C/ County/ State]) -> #N/A | F36: =E36*A36*C36 -> #N/A
A37: =Sheet1!C42 -> 0 | B37: =Sheet1!B42&" - #"&Sheet1!E42 -> - # | C37: =Sheet1!D42 -> 0 | D37: Hr | E37: =LOOKUP(Sheet1!E42,Table336789101112131415[Equip Number], Table336789101112131415[Sched C/ County/ State]) -> #N/A | F37: =E37*A37*C37 -> #N/A | G37: Work Order Number | J37: Work Completed
A38: Sub Total Equipment Rate | F38: {=SUM(IFERROR(F21:F37,0))} -> 0 | L38: District Supervisor | N38: Date
A39: Total Equipment Rate Days | E39: 1 | F39: =F38*K16 -> 0
A40: III. Material | K40: Engineering Dept Fund Verification | N40: Matching Allocation
...

Sheet Equipment Rates
A1: Genesee County Road Commission (FA- Specification and Rentals) 2026
A2: EQUIPMENT | F2: 2026 Hourly Rate | I2: 2025 Comparison
A3: Equip Number | B3: Description | C3: Model Year | D3: Make | E3: Model / Series | F3: Sched C/ County/ State | G3: W/Radio | H3: Column1 | I3: 2025 Rate | J3: 2025/26 Variance
A4: 100 | B4: Drone | C4: 2020 | D4: Matrice | E4: 210 V2 | F4: 10.75 | I4: 10.06 | J4: =Table336789101112131415[[#This Row],[Sched C/ County/ State]]-Table336789101112131415[[#This Row],[2025 Rate]] -> 0.69
A5: 101 | B5: Trimble S5 3" Robotic & TSC5 System | C5: 2021 | D5: Trimble | E5: TCS5 System | F5: 8.11 | I5: 7.59 | J5: =Table336789101112131415[[#This Row],[Sched C/ County/ State]]-Table336789101112131415[[#This Row],[2025 Rate]] -> 0.52
A6: 106 | B6: Envirosight Pole Camera | C6: 2021 | D6: Envirosight | F6: 16.27 | I6: 15.23 | J6: =Table336789101112131415[[#This Row],[Sched C/ County/ State]]-Table336789101112131415[[#This Row],[2025 Rate]] -> 1.04
A7: 309 | B7: Hot Patcher (Lease) | C7: 2017 | D7: KM International | E7: KM800TEDD | F7: 47.75 | I7: 44.68 | J7: =Table336789101112131415[[#This Row],[Sched C/ County/ State]]-Table336789101112131415[[#This Row],[2025 Rate]] -> 3.07
A8: 314 | B8: Liquid Spray System - Demo | C8: 2002 | D8: Force America | E8: SSC5100 | F8: 3.05 | I8: 2.85 | J8: =Table336789101112131415[[#This Row],[Sched C/ County/ State]]-Table336789101112131415[[#This Row],[2025 Rate]] -> 0.2
A9: 315 | B9: Anti-icing Unit 1250 Gal Tank - Demo | C9: 2002 | D9: Force America | E9: FA-1250-3L | F9: 20.91 | I9: 19.57 | J9: =Table336789101112131415[[#This Row],[Sched C/ County/ State]]-Table336789101112131415[[#This Row],[2025 Rate]] -> 1.34
A10: 316 | B10: Sign Truck | C10: 1993 | D10: International | E10: 4900 | F10: 33.4 | I10: 30.99 | J10: =Table336789101112131415[[#This Row],[Sched C/ County/ State]]-Table336789101112131415[[#This Row],[2025 Rate]] -> 2.41
A11: 317 | B11: Post Puller | F11: 1.2 | I11: 1.12 | J11: =Table336789101112131415[[#This Row],[Sched C/ County/ State]]-Table336789101112131415[[#This Row],[2025 Rate]] -> 0.08
A12: 318 | B12: Boom | C12: 1993 | D12: Versalift | E12: VST40001 | F12: 18.04 | I12: 16.88 | J12: =Table336789101112131415[[#This Row],[Sched C/ County/ State]]-Table336789101112131415[[#This Row],[2025 Rate]] -> 1.16
A13: 401 | B13: Global Positioning System | C13: 2010 | D13: Teletrac | E13: TM450 | F13: 0.78 | I13: 0.73 | J13: =Table336789101112131415[[#This Row],[Sched C/ County/ State]]-Table336789101112131415[[#This Row],[2025 Rate]] -> 0.05
A14: 402 | B14: Global Positioning System | C14: 2010 | D14: Teletrac | E14: TM450 | F14: 0.78 | I14: 0.73 | J14: =Table336789101112131415[[#This Row],[Sched C/ County/ State]]-Table336789101112131415[[#This Row],[2025 Rate]] -> 0.05
A15: 403 | B15: Global Positioning System | C15: 2010 | D15: Teletrac | E15: TM450 | F15: 0.78 | I15: 0.73 | J15: =Table336789101112131415[[#This Row],[Sched C/ County/ State]]-Table336789101112131415[[#This Row],[2025 Rate]] -> 0.05
A16: 404 | B16: Global Positioning System | C16: 2010 | D16: Teletrac | E16: TM450 | F16: 0.78 | I16: 0.73 | J16: =Table336789101112131415[[#This Row],[Sched C/ County/ State]]-Table336789101112131415[[#This Row],[2025 Rate]] -> 0.05
A17: 405 | B17: Global Positioning System | C17: 2010 | D17: Teletrac | E17: TM450 | F17: 0.78 | I17: 0.73 | J17: =Table336789101112131415[[#This Row],[Sched C/ County/ State]]-Table336789101112131415[[#This Row],[2025 Rate]] -> 0.05
A18: 406 | B18: Global Positioing System | C18: 2010 | D18: Teletrac | E18: TM450J | F18: 0.78 | I18: 0.73 | J18: =Table336789101112131415[[#This Row],[Sched C/ County/ State]]-Table336789101112131415[[#This Row],[2025 Rate]] -> 0.05
A19: 407 | B19: Global Positioning System | C19: 2010 | D19: Teletrac | E19: TM450 | F19: 0.78 | I19: 0.73 | J19: =Table336789101112131415[[#This Row],[Sched C/ County/ State]]-Table336789101112131415[[#This Row],[2025 Rate]] -> 0.05
A20: 408 | B20: Global Positioning System | C20: 2010 | D20: Teletrac | E20: TM450 | F20: 0.78 | I20: 0.73 | J20: =Table336789101112131415[[#This Row],[Sched C/ County/ State]]-Table336789101112131415[[#This Row],[2025 Rate]] -> 0.05
A21: 409 | B21: Global Positioning System | C21: 2010 | D21: Teletrac | E21: TM450 | F21: 0.78 | I21: 0.73 | J21: =Table336789101112131415[[#This Row],[Sched C/ County/ State]]-Table336789101112131415[[#This Row],[2025 Rate]] -> 0.05
A22: 417 | B22: 20" Chainsaw | C22: 2017 | D22: Husqvarna | E22: Rancher455 | F22: 6.98 | I22: 6.53 | J22: =Table336789101112131415[[#This Row],[Sched C/ County/ State]]-Table336789101112131415[[#This Row],[2025 Rate]] -> 0.45
A23: 419 | B23: 24" Chainsaw | C23: 2017 | D23: Husqvarna | E23: 365 | F23: 6.98 | I23: 6.53 | J23: =Table336789101112131415[[#This Row],[Sched C/ County/ State]]-Table336789101112131415[[#This Row],[2025 Rate]] -> 0.45
A24: 424 | B24: 14" Chainsaw | C24: 2017 | D24: Stihl | E24: MS193T | F24: 4.74 | I24: 4.44 | J24: =Table336789101112131415[[#This Row],[Sched C/ County/ State]]-Table336789101112131415[[#This Row],[2025 Rate]] -> 0.3
A25: 427 | B25: Global Positioning System | C25: 2008 | D25: Teletrac | E25: 700-0100 TM2 | F25: 0.78 | I25: 0.73 | J25: =Table336789101112131415[[#This Row],[Sched C/ County/ State]]-Table336789101112131415[[#This Row],[2025 Rate]] -> 0.05
A26: 431 | B26: Global Positioning System | C26: 2008 | D26: Teletrac | E26: 700-0100-TM2 | F26: 0.78 | I26: 0.73 | J26: =Table336789101112131415[[#This Row],[Sched C/ County/ State]]-Table336789101112131415[[#This Row],[2025 Rate]] -> 0.05
A27: 432 | B27: Global Positioning System | C27: 2010 | D27: Teletrac | E27: TM450 | F27: 0.78 | I27: 0.73 | J27: =Table336789101112131415[[#This Row],[Sched C/ County/ State]]-Table336789101112131415[[#This Row],[2025 Rate]] -> 0.05
A28: 433 | B28: Global Positioning System | C28: 2010 | D28: Teletrac | E28: TM450 | F28: 0.78 | I28: 0.73 | J28: =Table336789101112131415[[#This Row],[Sched C/ County/ State]]-Table336789101112131415[[#This Row],[2025 Rate]] -> 0.05
A29: 434 | B29: Global Positioning System | C29: 2010 | D29: Teletrac | E29: TM450 | F29: 0.78 | I29: 0.73 | J29: =Table336789101112131415[[#This Row],[Sched C/ County/ State]]-Table336789101112131415[[#This Row],[2025 Rate]] -> 0.05
A30: 435 | B30: Global Positioning System | C30: 2010 | D30: Teletrac | E30: TM450 | F30: 0.78 | I30: 0.73 | J30: =Table336789101112131415[[#This Row],[Sched C/ County/ State]]-Table336789101112131415[[#This Row],[2025 Rate]] -> 0.05
A31: 436 | B31: Global Positioning System | C31: 2010 | D31: Teletrac | E31: TM450 | F31: 0.78 | I31: 0.73 | J31: =Table336789101112131415[[#This Row],[Sched C/ County/ State]]-Table336789101112131415[[#This Row],[2025 Rate]] -> 0.05
A32: 437 | B32: Global Positioning System | C32: 2010 | D32: Teletrac | E32: TM450 | F32: 0.78 | I32: 0.73 | J32: =Table336789101112131415[[#This Row],[Sched C/ County/ State]]-Table336789101112131415[[#This Row],[2025 Rate]] -> 0.05
A33: 438 | B33: Global Positioning System | C33: 2010 | D33: Teletrac | E33: TM450 | F33: 0.78 | I33: 0.73 | J33: =Table336789101112131415[[#This Row],[Sched C/ County/ State]]-Table336789101112131415[[#This Row],[2025 Rate]] -> 0.05
A34: 439 | B34: Salt Calibrator | C34: 2018 | D34: Scale Tec | E34: IV-PSF | F34: 6.49 | I34: 6.07 | J34: =Table336789101112131415[[#This Row],[Sched C/ County/ State]]-Table336789101112131415[[#This Row],[2025 Rate]] -> 0.42
A35: 440 | B35: Distance Meter | C35: 2017 | D35: FastMeasure | E35: FM-GPS | F35: 0.1 | I35: 0.09 | J35: =Table336789101112131415[[#This Row],[Sched C/ County/ State]]-Table336789101112131415[[#This Row],[2025 Rate]] -> 0.01
... A53: 462 | B53: De-Icing Liquid Tank | C53: 2018 | D53: Monroe | E53: DCDFV-11.510067 | F53: 32.76 | I53: 30.66 | J53: =Table336789101112131415[[#This Row],[Sched C/ County/ State]]-Table336789101112131415[[#This Row],[2025 Rate]] -> 2.1
A54: 463 | B54: De-Icing Pump | C54: 2018 | D54: Banjo | E54: 200 | F54: 6.98 | I54: 6.48 | J54: =Table336789101112131415[[#This Row],[Sched C/ County/ State]]-Table336789101112131415[[#This Row],[2025 Rate]] -> 0.5
A55: 464 | B55: De-Icing Pump | C55: 2018 | D55: Banjo | E55: 200 | F55: 6.98 | I55: 6.48 | J55: =Table336789101112131415[[#This Row],[Sched C/ County/ State]]-Table336789101112131415[[#This Row],[2025 Rate]] -> 0.5
A56: 465 | B56: Patching Shelf | C56: 2018 | D56: Own Make | F56: 0.59 | I56: 0.55 | J56: =Table336789101112131415[[#This Row],[Sched C/ County/ State]]-Table336789101112131415[[#This Row],[2025 Rate]] -> 0.04
A57: 466 | B57: De-Icing Liquid Tank | C57: 2018 | D57: Monroe | E57: DCDFV-11.510067 | F57: 32.76 | I57: 30.66 | J57: =Table336789101112131415[[#This Row],[Sched C/ County/ State]]-Table336789101112131415[[#This Row],[2025 Rate]] -> 2.1
...
